<?xml version="1.0" ?>
<!-- =================================================================================== -->
<!-- |    This document was autogenerated by xacro from /home/ry0/Workspace/ROS/nachi_ws/src/nachi_project/nachi_description/robots/mz07/mz07.urdf.xacro | -->
<!-- |    EDITING THIS FILE BY HAND IS NOT RECOMMENDED                                 | -->
<!-- =================================================================================== -->
<robot name="mz07" xmlns:xacro="http://ros.org/wiki/xacro">
  <material name="black">
    <color rgba="0.0 0.0 0.0 1.0"/>
  </material>
  <material name="blue">
    <color rgba="0.0 0.0 0.8 1.0"/>
  </material>
  <material name="green">
    <color rgba="0.0 0.8 0.0 1.0"/>
  </material>
  <material name="grey">
    <color rgba="0.2 0.2 0.2 1.0"/>
  </material>
  <material name="orange">
    <color rgba="1.0 0.423529411765 0.0392156862745 1.0"/>
  </material>
  <material name="brown">
    <color rgba="0.870588235294 0.811764705882 0.764705882353 1.0"/>
  </material>
  <material name="red">
    <color rgba="0.8 0.0 0.0 1.0"/>
  </material>
  <material name="white">
    <color rgba="1.0 1.0 1.0 1.0"/>
  </material>
  <link name="world"/>
  <link name="base_link">
    <visual>
      <geometry>
        <mesh filename="package://nachi_description/meshes/mz07/visual/base_link.dae"/>
      </geometry>
    </visual>
    <collision>
      <geometry>
        <mesh filename="package://nachi_description/meshes/mz07/collision/base_link.stl"/>
      </geometry>
    </collision>
    <inertial>
      <mass value="3.0"/>
      <inertia ixx="0.001" ixy="0" ixz="0" iyy="0.001" iyz="0" izz="0.001"/>
    </inertial>
  </link>
  <link name="link_1">
    <visual>
      <geometry>
        <mesh filename="package://nachi_description/meshes/mz07/visual/link_1.dae"/>
      </geometry>
    </visual>
    <collision>
      <geometry>
        <mesh filename="package://nachi_description/meshes/mz07/collision/link_1.stl"/>
      </geometry>
    </collision>
    <inertial>
      <mass value="3.0"/>
      <inertia ixx="0.001" ixy="0" ixz="0" iyy="0.001" iyz="0" izz="0.001"/>
    </inertial>
  </link>
  <link name="link_2">
    <visual>
      <geometry>
        <mesh filename="package://nachi_description/meshes/mz07/visual/link_2.dae"/>
      </geometry>
    </visual>
    <collision>
      <geometry>
        <mesh filename="package://nachi_description/meshes/mz07/collision/link_2.stl"/>
      </geometry>
    </collision>
    <inertial>
      <mass value="3.0"/>
      <inertia ixx="0.001" ixy="0" ixz="0" iyy="0.001" iyz="0" izz="0.001"/>
    </inertial>
  </link>
  <link name="link_3">
    <visual>
      <geometry>
        <mesh filename="package://nachi_description/meshes/mz07/visual/link_3.dae"/>
      </geometry>
    </visual>
    <collision>
      <geometry>
        <mesh filename="package://nachi_description/meshes/mz07/collision/link_3.stl"/>
      </geometry>
    </collision>
    <inertial>
      <mass value="3.0"/>
      <inertia ixx="0.001" ixy="0" ixz="0" iyy="0.001" iyz="0" izz="0.001"/>
    </inertial>
  </link>
  <link name="link_4">
    <visual>
      <geometry>
        <mesh filename="package://nachi_description/meshes/mz07/visual/link_4.dae"/>
      </geometry>
    </visual>
    <collision>
      <geometry>
        <mesh filename="package://nachi_description/meshes/mz07/collision/link_4.stl"/>
      </geometry>
    </collision>
    <inertial>
      <mass value="3.0"/>
      <inertia ixx="0.001" ixy="0" ixz="0" iyy="0.001" iyz="0" izz="0.001"/>
    </inertial>
  </link>
  <link name="link_5">
    <visual>
      <geometry>
        <mesh filename="package://nachi_description/meshes/mz07/visual/link_5.dae"/>
      </geometry>
    </visual>
    <collision>
      <geometry>
        <mesh filename="package://nachi_description/meshes/mz07/collision/link_5.stl"/>
      </geometry>
    </collision>
    <inertial>
      <mass value="3.0"/>
      <inertia ixx="0.001" ixy="0" ixz="0" iyy="0.001" iyz="0" izz="0.001"/>
    </inertial>
  </link>
  <link name="link_6">
    <visual>
      <geometry>
        <mesh filename="package://nachi_description/meshes/mz07/visual/link_6.dae"/>
      </geometry>
    </visual>
    <collision>
      <geometry>
        <mesh filename="package://nachi_description/meshes/mz07/collision/link_6.stl"/>
      </geometry>
    </collision>
    <inertial>
      <mass value="3.0"/>
      <inertia ixx="0.001" ixy="0" ixz="0" iyy="0.001" iyz="0" izz="0.001"/>
    </inertial>
  </link>
  <link name="tool0"/>
  <joint name="world" type="fixed">
    <parent link="world"/>
    <child link="base_link"/>
  </joint>
  <joint name="J1" type="revolute">
    <origin rpy="0 0 0" xyz="0 0 0.197"/>
    <parent link="base_link"/>
    <child link="link_1"/>
    <axis xyz="0 0 1"/>
    <dynamics damping="0.7" friction="0.7"/>
    <limit effort="30.0" lower="-2.96705981" upper="2.96705981" velocity="7.85398185"/>
  </joint>
  <joint name="J2" type="revolute">
    <origin rpy="0 0 0" xyz="0.05 0 0.148"/>
    <parent link="link_1"/>
    <child link="link_2"/>
    <axis xyz="0 1 0"/>
    <dynamics damping="0.7" friction="0.7"/>
    <limit effort="30.0" lower="-1.39626344" upper="2.356194555" velocity="6.63225134"/>
  </joint>
  <joint name="J3" type="revolute">
    <origin rpy="0 0 0" xyz="0 0 0.33"/>
    <parent link="link_2"/>
    <child link="link_3"/>
    <axis xyz="0 1 0"/>
    <dynamics damping="0.7" friction="0.7"/>
    <limit effort="30.0" lower="-3.14159274" upper="0.802851478" velocity="9.07571236"/>
  </joint>
  <joint name="J4" type="revolute">
    <origin rpy="0 0 0" xyz="0.09 0 0.045"/>
    <parent link="link_3"/>
    <child link="link_4"/>
    <axis xyz="1 0 0"/>
    <dynamics damping="0.7" friction="0.7"/>
    <limit effort="30.0" lower="-3.31612567" upper="3.31612567" velocity="9.59931115"/>
  </joint>
  <joint name="J5" type="revolute">
    <origin rpy="0 0 0" xyz="0.25 0 0"/>
    <parent link="link_4"/>
    <child link="link_5"/>
    <axis xyz="0 1 0"/>
    <dynamics damping="0.7" friction="0.7"/>
    <limit effort="30.0" lower="-2.09439516" upper="2.09439516" velocity="9.59931115"/>
  </joint>
  <joint name="J6" type="revolute">
    <origin rpy="0 0 0" xyz="0.063 0 0"/>
    <parent link="link_5"/>
    <child link="link_6"/>
    <axis xyz="1 0 0"/>
    <dynamics damping="0.7" friction="0.7"/>
    <limit effort="30.0" lower="-6.28318548" upper="6.28318548" velocity="17.453293"/>
  </joint>
  <joint name="joint_tool0" type="fixed">
    <origin rpy="0 0 0" xyz="0.0195 0 0"/>
    <parent link="link_6"/>
    <child link="tool0"/>
  </joint>
</robot>

