<?xml version="1.0" ?>
<!-- =================================================================================== -->
<!-- |    This document was autogenerated by xacro from mz07.sensor.urdf.xacro         | -->
<!-- |    EDITING THIS FILE BY HAND IS NOT RECOMMENDED                                 | -->
<!-- =================================================================================== -->
<robot name="mz07" xmlns:xacro="http://ros.org/wiki/xacro">
  <!-- File Include -->
  <!-- Include -->
  <material name="black">
    <color rgba="0.0 0.0 0.0 1.0"/>
  </material>
  <material name="blue">
    <color rgba="0.0 0.0 0.8 1.0"/>
  </material>
  <material name="green">
    <color rgba="0.0 0.8 0.0 1.0"/>
  </material>
  <material name="grey">
    <color rgba="0.2 0.2 0.2 1.0"/>
  </material>
  <material name="orange">
    <color rgba="1.0 0.423529411765 0.0392156862745 1.0"/>
  </material>
  <material name="brown">
    <color rgba="0.870588235294 0.811764705882 0.764705882353 1.0"/>
  </material>
  <material name="red">
    <color rgba="0.8 0.0 0.0 1.0"/>
  </material>
  <material name="white">
    <color rgba="1.0 1.0 1.0 1.0"/>
  </material>
  <!-- Radius Limits -->
  <!-- Velocity Limits -->
  <!-- Link -->
  <link name="world"/>
  <link name="base_link">
    <visual>
      <geometry>
        <mesh filename="package://nachi_description/meshes/mz07/visual/base_link.dae"/>
      </geometry>
    </visual>
    <collision>
      <geometry>
        <mesh filename="package://nachi_description/meshes/mz07/collision/base_link.stl"/>
      </geometry>
    </collision>
    <inertial>
      <mass value="9.522365"/>
      <inertia ixx="0.144495" ixy="-9e-06" ixz="-0.03076" iyy="0.183352" iyz="-3.7e-05" izz="0.079873"/>
    </inertial>
  </link>
  <link name="link_1">
    <visual>
      <geometry>
        <mesh filename="package://nachi_description/meshes/mz07/visual/link_1.dae"/>
      </geometry>
    </visual>
    <collision>
      <geometry>
        <mesh filename="package://nachi_description/meshes/mz07/collision/link_1.stl"/>
      </geometry>
    </collision>
    <inertial>
      <mass value="5.61696"/>
      <inertia ixx="0.087433" ixy="0.0" ixz="0.013287" iyy="0.073064" iyz="1.9e-05" izz="0.039829"/>
    </inertial>
  </link>
  <link name="link_2">
    <visual>
      <geometry>
        <mesh filename="package://nachi_description/meshes/mz07/visual/link_2.dae"/>
      </geometry>
    </visual>
    <collision>
      <geometry>
        <mesh filename="package://nachi_description/meshes/mz07/collision/link_2.stl"/>
      </geometry>
    </collision>
    <inertial>
      <mass value="7.350069"/>
      <inertia ixx="0.299465" ixy="-1e-05" ixz="-0.012735" iyy="0.279554" iyz="5.3e-05" izz="0.035911"/>
    </inertial>
  </link>
  <link name="link_3">
    <visual>
      <geometry>
        <mesh filename="package://nachi_description/meshes/mz07/visual/link_3.dae"/>
      </geometry>
    </visual>
    <collision>
      <geometry>
        <mesh filename="package://nachi_description/meshes/mz07/collision/link_3.stl"/>
      </geometry>
    </collision>
    <inertial>
      <mass value="3.724767"/>
      <inertia ixx="0.011733" ixy="4.3e-05" ixz="0.000461" iyy="0.019531" iyz="2.4e-05" izz="0.014154"/>
    </inertial>
  </link>
  <link name="link_4">
    <visual>
      <geometry>
        <mesh filename="package://nachi_description/meshes/mz07/visual/link_4.dae"/>
      </geometry>
    </visual>
    <collision>
      <geometry>
        <mesh filename="package://nachi_description/meshes/mz07/collision/link_4.stl"/>
      </geometry>
    </collision>
    <inertial>
      <mass value="3.245188"/>
      <inertia ixx="0.007141" ixy="0.000562" ixz="0.000255" iyy="0.054197" iyz="2.4e-05" izz="0.056111"/>
    </inertial>
  </link>
  <link name="link_5">
    <visual>
      <geometry>
        <mesh filename="package://nachi_description/meshes/mz07/visual/link_5.dae"/>
      </geometry>
    </visual>
    <collision>
      <geometry>
        <mesh filename="package://nachi_description/meshes/mz07/collision/link_5.stl"/>
      </geometry>
    </collision>
    <inertial>
      <mass value="0.501938"/>
      <inertia ixx="0.000539" ixy="1e-06" ixz="0.0" iyy="0.000892" iyz="-1e-06" izz="0.000962"/>
    </inertial>
  </link>
  <link name="link_6">
    <visual>
      <geometry>
        <mesh filename="package://nachi_description/meshes/mz07/visual/link_6.dae"/>
      </geometry>
    </visual>
    <collision>
      <geometry>
        <mesh filename="package://nachi_description/meshes/mz07/collision/link_6.stl"/>
      </geometry>
    </collision>
    <inertial>
      <mass value="0.038575"/>
      <inertia ixx="0.0005" ixy="0.0" ixz="0.0" iyy="0.0005" iyz="0.0" izz="0.0005"/>
    </inertial>
  </link>
  <!--
  <xacro:link_v1 name="link_6" mass="0.038575"
				 ixx="0.000027" ixy="0.000000" ixz="0.000000"
				 iyy="0.000016" iyz="0.000000"
				 izz="0.000017"/> -->
  <link name="tool0"/>
  <!-- Joint -->
  <joint name="world" type="fixed">
    <parent link="world"/>
    <child link="base_link"/>
  </joint>
  <joint name="J1" type="revolute">
    <origin rpy="0 0 0" xyz="0 0 0.197"/>
    <parent link="base_link"/>
    <child link="link_1"/>
    <axis xyz="0 0 1"/>
    <dynamics damping="0.7" friction="0.7"/>
    <limit effort="30.0" lower="-2.96705981" upper="2.96705981" velocity="7.85398185"/>
  </joint>
  <joint name="J2" type="revolute">
    <origin rpy="0 0 0" xyz="0.05 0 0.148"/>
    <parent link="link_1"/>
    <child link="link_2"/>
    <axis xyz="0 1 0"/>
    <dynamics damping="0.7" friction="0.7"/>
    <limit effort="30.0" lower="-1.39626344" upper="2.356194555" velocity="6.63225134"/>
  </joint>
  <joint name="J3" type="revolute">
    <origin rpy="0 0 0" xyz="0 0 0.33"/>
    <parent link="link_2"/>
    <child link="link_3"/>
    <axis xyz="0 1 0"/>
    <dynamics damping="0.7" friction="0.7"/>
    <limit effort="30.0" lower="-3.14159274" upper="0.802851478" velocity="9.07571236"/>
  </joint>
  <joint name="J4" type="revolute">
    <origin rpy="0 0 0" xyz="0.09 0 0.045"/>
    <parent link="link_3"/>
    <child link="link_4"/>
    <axis xyz="1 0 0"/>
    <dynamics damping="0.7" friction="0.7"/>
    <limit effort="30.0" lower="-3.31612567" upper="3.31612567" velocity="9.59931115"/>
  </joint>
  <joint name="J5" type="revolute">
    <origin rpy="0 0 0" xyz="0.25 0 0"/>
    <parent link="link_4"/>
    <child link="link_5"/>
    <axis xyz="0 1 0"/>
    <dynamics damping="0.7" friction="0.7"/>
    <limit effort="30.0" lower="-2.09439516" upper="2.09439516" velocity="9.59931115"/>
  </joint>
  <joint name="J6" type="revolute">
    <origin rpy="0 0 0" xyz="0.063 0 0"/>
    <parent link="link_5"/>
    <child link="link_6"/>
    <axis xyz="1 0 0"/>
    <dynamics damping="0.7" friction="0.7"/>
    <limit effort="30.0" lower="-6.28318548" upper="6.28318548" velocity="17.453293"/>
  </joint>
  <joint name="joint_tool0" type="fixed">
    <origin rpy="0 0 0" xyz="0.0195 0 0"/>
    <parent link="link_6"/>
    <child link="tool0"/>
  </joint>
  <!-- transmission -->
  <transmission name="transmission_1">
    <type>transmission_interface/SimpleTransmission</type>
    <joint name="J1">
      <hardwareInterface>PositionJointInterface</hardwareInterface>
    </joint>
    <actuator name="motor_1">
      <hardwareInterface>PositionJointInterface</hardwareInterface>
      <mechanicalReduction>1</mechanicalReduction>
    </actuator>
  </transmission>
  <transmission name="transmission_2">
    <type>transmission_interface/SimpleTransmission</type>
    <joint name="J2">
      <hardwareInterface>PositionJointInterface</hardwareInterface>
    </joint>
    <actuator name="motor_2">
      <hardwareInterface>PositionJointInterface</hardwareInterface>
      <mechanicalReduction>1</mechanicalReduction>
    </actuator>
  </transmission>
  <transmission name="transmission_3">
    <type>transmission_interface/SimpleTransmission</type>
    <joint name="J3">
      <hardwareInterface>PositionJointInterface</hardwareInterface>
    </joint>
    <actuator name="motor_3">
      <hardwareInterface>PositionJointInterface</hardwareInterface>
      <mechanicalReduction>1</mechanicalReduction>
    </actuator>
  </transmission>
  <transmission name="transmission_4">
    <type>transmission_interface/SimpleTransmission</type>
    <joint name="J4">
      <hardwareInterface>PositionJointInterface</hardwareInterface>
    </joint>
    <actuator name="motor_4">
      <hardwareInterface>PositionJointInterface</hardwareInterface>
      <mechanicalReduction>1</mechanicalReduction>
    </actuator>
  </transmission>
  <transmission name="transmission_5">
    <type>transmission_interface/SimpleTransmission</type>
    <joint name="J5">
      <hardwareInterface>PositionJointInterface</hardwareInterface>
    </joint>
    <actuator name="motor_5">
      <hardwareInterface>PositionJointInterface</hardwareInterface>
      <mechanicalReduction>1</mechanicalReduction>
    </actuator>
  </transmission>
  <transmission name="transmission_6">
    <type>transmission_interface/SimpleTransmission</type>
    <joint name="J6">
      <hardwareInterface>PositionJointInterface</hardwareInterface>
    </joint>
    <actuator name="motor_6">
      <hardwareInterface>PositionJointInterface</hardwareInterface>
      <mechanicalReduction>1</mechanicalReduction>
    </actuator>
  </transmission>
  <!-- gazebo -->
  <gazebo>
    <plugin filename="libgazebo_ros_control.so" name="gazebo_ros_control">
      <robotNamespace>/mz07</robotNamespace>
      <robotSimType>gazebo_ros_control/DefaultRobotHWSim</robotSimType>
    </plugin>
  </gazebo>
  <gazebo reference="base_link">
    <mu1>0.2</mu1>
    <mu2>0.2</mu2>
    <selfCollide>true</selfCollide>
    <!--     <turnGravityOff>true</turnGravityOff> -->
  </gazebo>
  <gazebo reference="link_1">
    <mu1>0.2</mu1>
    <mu2>0.2</mu2>
    <selfCollide>true</selfCollide>
    <!--     <turnGravityOff>true</turnGravityOff> -->
  </gazebo>
  <gazebo reference="link_2">
    <mu1>0.2</mu1>
    <mu2>0.2</mu2>
    <selfCollide>true</selfCollide>
    <!--     <turnGravityOff>true</turnGravityOff> -->
  </gazebo>
  <gazebo reference="link_3">
    <mu1>0.2</mu1>
    <mu2>0.2</mu2>
    <selfCollide>true</selfCollide>
    <!--     <turnGravityOff>true</turnGravityOff> -->
  </gazebo>
  <gazebo reference="link_4">
    <mu1>0.2</mu1>
    <mu2>0.2</mu2>
    <selfCollide>true</selfCollide>
    <!--     <turnGravityOff>true</turnGravityOff> -->
  </gazebo>
  <gazebo reference="link_5">
    <mu1>0.2</mu1>
    <mu2>0.2</mu2>
    <selfCollide>true</selfCollide>
    <!--     <turnGravityOff>true</turnGravityOff> -->
  </gazebo>
  <gazebo reference="link_6">
    <mu1>0.2</mu1>
    <mu2>0.2</mu2>
    <selfCollide>true</selfCollide>
    <!--     <turnGravityOff>true</turnGravityOff> -->
  </gazebo>
  <!-- add Kinect V2 -->
  <!-- Link -->
  <link name="kinect2_link">
    <visual>
      <geometry>
        <mesh filename="package://nachi_description/meshes/sensor/visual/COLLADA/kinect2.dae"/>
      </geometry>
    </visual>
    <collision>
      <origin xyz="0 0 0.041"/>
      <geometry>
        <box size="0.065 0.25 0.082"/>
      </geometry>
    </collision>
    <inertial>
      <mass value="0.935"/>
      <inertia ixx="0.0053937" ixy="0" ixz="0" iyy="0.00085311" iyz="0" izz="0.00519899"/>
    </inertial>
  </link>
  <link name="kinect2_rgb_optical_frame"/>
  <!-- Joint -->
  <joint name="joint_kinect2" type="fixed">
    <origin rpy="0 0.17453293 3.14159274" xyz="1.5 0 0.4"/>
    <parent link="world"/>
    <child link="kinect2_link"/>
  </joint>
  <joint name="joint_rgb_kinect2" type="fixed">
    <origin rpy="1.57079637 3.14159274 1.57079637"/>
    <parent link="kinect2_link"/>
    <child link="kinect2_rgb_optical_frame"/>
  </joint>
  <!-- Gazebo -->
  <gazebo reference="kinect2_link">
    <sensor name="kinect2" type="depth">
      <always_on>true</always_on>
      <update_rate>6.0</update_rate>
      <camera>
        <horizontal_fov>1.4678219413</horizontal_fov>
        <!-- <vertical_fov>${53.8*M_PI/180.0}</vertical_fov> -->
        <image>
          <format>R8G8B8</format>
          <width>512</width>
          <height>424</height>
        </image>
        <clip>
          <near>0.05</near>
          <far>4.5</far>
        </clip>
      </camera>
      <plugin filename="libgazebo_ros_openni_kinect.so" name="kinect2_camera_controller">
        <cameraName>kinect2</cameraName>
        <alwaysOn>true</alwaysOn>
        <updateRate>6.0</updateRate>
        <imageTopicName>hd/image_color</imageTopicName>
        <depthImageTopicName>hd/image_depth</depthImageTopicName>
        <pointCloudTopicName>hd/points</pointCloudTopicName>
        <cameraInfoTopicName>hd/camera_info</cameraInfoTopicName>
        <depthImageCameraInfoTopicName>hd/camera_info</depthImageCameraInfoTopicName>
        <frameName>kinect2_rgb_optical_frame</frameName>
        <!--           <baseline>0.1</baseline>
          <distortion_k1>0.0</distortion_k1>
          <distortion_k2>0.0</distortion_k2>
          <distortion_k3>0.0</distortion_k3>
          <distortion_t1>0.0</distortion_t1>
          <distortion_t2>0.0</distortion_t2> -->
        <pointCloudCutoff>0.05</pointCloudCutoff>
        <pointCloudCutoffMax>4.5</pointCloudCutoffMax>
      </plugin>
    </sensor>
  </gazebo>
</robot>

